Workbook

Sheet Content Plan
A1: Unpack & Explain: 30-Day Content Plan & Tracker
A2: Blue text = inputs you edit. Black = formulas. Fill in the metrics columns after posting; the Summary tab updates itself.
A4: ID | B4: Week | C4: Planned date | D4: Format | E4: Sub-area | F4: Topic | G4: Hook idea | H4: Source / verify before posting | I4: Status | J4: Reach | K4: Avg watch time % | L4: Likes | M4: Comments | N4: Shares | O4: Saves | P4: Follows gained | Q4: Engagement rate | R4: Share + save rate | S4: Follows per 1k reach | T4: Notes
A5: 1 | B5: 1 | C5: 46328 | D5: E | E5: Money & payments | F5: How a card payment works | G5: You tap your card. Up to 5 companies get involved in 2 seconds. | H5: Card network / acquirer docs; verify settlement timing | I5: Scripted | Q5: =IF(J5>0,(L5+M5+N5+O5)/J5,"") | R5: =IF(J5>0,(N5+O5)/J5,"") | S5: =IF(J5>0,P5/J5*1000,"")
A6: 2 | B6: 1 | C6: 46329 | D6: E | E6: Everyday tech | F6: How GPS finds you | G6: GPS doesn't track you. Your phone just listens. | H6: GPS.gov; verify relativity figure | I6: Scripted | Q6: =IF(J6>0,(L6+M6+N6+O6)/J6,"") | R6: =IF(J6>0,(N6+O6)/J6,"") | S6: =IF(J6>0,P6/J6*1000,"")
A7: 3 | B7: 1 | C7: 46331 | D7: F | E7: Aviation & engineering | F7: How a jet engine works + Gimli Glider | G7: A passenger jet ran out of fuel at 41,000 ft. Both engines died. | H7: Canadian investigation into Air Canada Flight 143 (1983) | I7: Scripted | Q7: =IF(J7>0,(L7+M7+N7+O7)/J7,"") | R7: =IF(J7>0,(N7+O7)/J7,"") | S7: =IF(J7>0,P7/J7*1000,"")
A8: 4 | B8: 1 | C8: 46332 | D8: Q | E8: Aviation & engineering | F8: Myth: planes fly because air pushes up from below | G8: Most people explain lift wrong. | H8: NASA Glenn 'lift' explainer pages | I8: Scripted | Q8: =IF(J8>0,(L8+M8+N8+O8)/J8,"") | R8: =IF(J8>0,(N8+O8)/J8,"") | S8: =IF(J8>0,P8/J8*1000,"")
A9: C1 | B9: 1 | C9: 46330 | D9: Carousel | E9: Money & payments | F9: 5 steps of a card payment | G9: Saveable cheat sheet | H9: Reuse facts from post 1 | I9: Idea | Q9: =IF(J9>0,(L9+M9+N9+O9)/J9,"") | R9: =IF(J9>0,(N9+O9)/J9,"") | S9: =IF(J9>0,P9/J9*1000,"")
A10: 5 | B10: 2 | C10: 46335 | D10: E | E10: Everyday tech | F10: How WiFi works | G10: WiFi is just radio, and your router is a tiny radio station. | H10: IEEE / Wi-Fi Alliance basics | I10: Idea | Q10: =IF(J10>0,(L10+M10+N10+O10)/J10,"") | R10: =IF(J10>0,(N10+O10)/J10,"") | S10: =IF(J10>0,P10/J10*1000,"")
A11: 6 | B11: 2 | C11: 46336 | D11: F | E11: Money & payments | F11: How stock exchanges match orders + Knight Capital | G11: A software glitch lost $440M in 45 minutes. | H11: SEC order on Knight Capital (2013) | I11: Idea | Q11: =IF(J11>0,(L11+M11+N11+O11)/J11,"") | R11: =IF(J11>0,(N11+O11)/J11,"") | S11: =IF(J11>0,P11/J11*1000,"")
A12: 7 | B12: 2 | C12: 46338 | D12: E | E12: Money & payments | F12: How credit scores work | G12: Your score is a guess about your future. | H12: Bureau/FICO public documentation | I12: Idea | Q12: =IF(J12>0,(L12+M12+N12+O12)/J12,"") | R12: =IF(J12>0,(N12+O12)/J12,"") | S12: =IF(J12>0,P12/J12*1000,"") | T12: Scores differ by country; keep it general
A13: 8 | B13: 2 | C13: 46339 | D13: Q | E13: Everyday tech | F13: Why airplane mode exists | G13: What actually happens if you don't switch it on? | H13: Aviation authority guidance | I13: Idea | Q13: =IF(J13>0,(L13+M13+N13+O13)/J13,"") | R13: =IF(J13>0,(N13+O13)/J13,"") | S13: =IF(J13>0,P13/J13*1000,"")
A14: C2 | B14: 2 | C14: 46337 | D14: Carousel | E14: Everyday tech | F14: How GPS works in 4 steps | G14: Saveable cheat sheet | H14: Reuse facts from post 2 | I14: Idea | Q14: =IF(J14>0,(L14+M14+N14+O14)/J14,"") | R14: =IF(J14>0,(N14+O14)/J14,"") | S14: =IF(J14>0,P14/J14*1000,"")
A15: 9 | B15: 3 | C15: 46342 | D15: F | E15: Aviation & engineering | F15: How bridges carry load + Tacoma Narrows | G15: A bridge tore itself apart in a light wind. | H15: Washington State archives / FHWA | I15: Idea | Q15: =IF(J15>0,(L15+M15+N15+O15)/J15,"") | R15: =IF(J15>0,(N15+O15)/J15,"") | S15: =IF(J15>0,P15/J15*1000,"")
A16: 10 | B16: 3 | C16: 46343 | D16: E | E16: Everyday tech | F16: How undersea cables carry the internet | G16: Most intercontinental data travels under the ocean. | H16: TeleGeography; verify the percentage | I16: Idea | Q16: =IF(J16>0,(L16+M16+N16+O16)/J16,"") | R16: =IF(J16>0,(N16+O16)/J16,"") | S16: =IF(J16>0,P16/J16*1000,"") | T16: Check the exact figure before using any number
A17: 11 | B17: 3 | C17: 46345 | D17: E | E17: Aviation & engineering | F17: How a plane's autopilot works | G17: Autopilot isn't flying the plane. It's following instructions. | H17: Aircraft manufacturer / FAA docs | I17: Idea | Q17: =IF(J17>0,(L17+M17+N17+O17)/J17,"") | R17: =IF(J17>0,(N17+O17)/J17,"") | S17: =IF(J17>0,P17/J17*1000,"")
A18: 12 | B18: 3 | C18: 46346 | D18: Q | E18: Everyday tech | F18: Myth: 'Cloud storage is in the sky' | G18: The cloud is a very real building. | H18: Cloud provider data center docs | I18: Idea | Q18: =IF(J18>0,(L18+M18+N18+O18)/J18,"") | R18: =IF(J18>0,(N18+O18)/J18,"") | S18: =IF(J18>0,P18/J18*1000,"")
A19: C3 | B19: 3 | C19: 46344 | D19: Carousel | E19: Aviation & engineering | F19: Jet engine in 4 stages | G19: Suck, squeeze, bang, blow | H19: Reuse facts from post 3 | I19: Idea | Q19: =IF(J19>0,(L19+M19+N19+O19)/J19,"") | R19: =IF(J19>0,(N19+O19)/J19,"") | S19: =IF(J19>0,P19/J19*1000,"")
A20: 13 | B20: 4 | C20: 46349 | D20: F | E20: Aviation & engineering | F20: Unit conversions + Mars Climate Orbiter | G20: A $125M spacecraft was lost over a unit mix-up. | H20: NASA/JPL Mishap Investigation Board report | I20: Idea | Q20: =IF(J20>0,(L20+M20+N20+O20)/J20,"") | R20: =IF(J20>0,(N20+O20)/J20,"") | S20: =IF(J20>0,P20/J20*1000,"") | T20: Same theme as post 3 (unit mix-up). Consider swapping to avoid repeating.
A21: 14 | B21: 4 | C21: 46350 | D21: E | E21: Everyday tech | F21: How a QR code stores data | G21: A QR code is a tiny grid of yes/no answers. | H21: ISO/IEC 18004 overview | I21: Idea | Q21: =IF(J21>0,(L21+M21+N21+O21)/J21,"") | R21: =IF(J21>0,(N21+O21)/J21,"") | S21: =IF(J21>0,P21/J21*1000,"")
A22: 15 | B22: 4 | C22: 46352 | D22: E | E22: Money & payments | F22: How banks move money internationally (SWIFT) | G22: Sending $100 abroad can take 3 banks. | H22: SWIFT public docs; verify | I22: Idea | Q22: =IF(J22>0,(L22+M22+N22+O22)/J22,"") | R22: =IF(J22>0,(N22+O22)/J22,"") | S22: =IF(J22>0,P22/J22*1000,"")
A23: 16 | B23: 4 | C23: 46353 | D23: Q | E23: Everyday tech | F23: Myth: 'Your phone needs a signal to use GPS' | G23: GPS works with no signal at all. | H23: GPS.gov | I23: Idea | Q23: =IF(J23>0,(L23+M23+N23+O23)/J23,"") | R23: =IF(J23>0,(N23+O23)/J23,"") | S23: =IF(J23>0,P23/J23*1000,"") | T23: Pairs with post 2
A24: C4 | B24: 4 | C24: 46351 | D24: Carousel | E24: Mixed | F24: Best-performing topic as a recap | G24: Decide from your own data | H24: Pick after reviewing the Summary tab | I24: Idea | Q24: =IF(J24>0,(L24+M24+N24+O24)/J24,"") | R24: =IF(J24>0,(N24+O24)/J24,"") | S24: =IF(J24>0,P24/J24*1000,"")
A26: Legend
A27: E | C27: Pure explainer: saves, shares, authority
A28: F | C28: Explainer + failure story: reach and watch time
A29: Q | C29: Quick myth / fact: fast to make on busy days
A30: Carousel | C30: Saveable cheat sheet: saves and shares
A31: Metrics | C31: Engagement rate = (likes + comments + shares + saves) / reach. Watch time % as a fraction of video length (e.g. 45%).
A33: Dates assume a Monday 2 Nov 2026 start (reels Mon/Tue/Thu/Fri, carousel Wed). Edit the Planned date column if you start later.

Sheet Scripts
A1: Week 1 Scripts (35-52 sec each)
A2: Template: Question, Hook, Setup, Mechanism, Payoff, Congrats, CTA. Question asks the viewer about the topic and ends with '?'. Congrats starts with 'Congrats,' (comma, not '!'). CTA is always 'Follow Unpack and Explain for how things actually work.' Target 100-130 spoken words per reel. Figures marked 'verify' need a source check before posting.
A3: Speaking pace (words per second) | D3: 2.5 | E3: Assumption: a typical AI voiceover reads roughly 2.5 words/second (about 150 wpm). Change it to match the voice you pick.
A5: Post | B5: Format | C5: Section | D5: Time | E5: Voiceover | F5: Visual / animation | G5: Words | H5: Est. seconds
A6: Post 1 | E | How a card payment works
A7: 1 | B7: E | C7: Question | D7: 0-4s | E7: Do you know what really happens when you tap your card? | F7: Question card (template). | G7: =LEN(TRIM(E7))-LEN(SUBSTITUTE(TRIM(E7)," ",""))+1 | H7: =G7/$D$3
A8: 1 | B8: E | C8: Hook | D8: 4-12s | E8: You tap your card, and it's approved in two seconds. In that time, up to five companies talk about you. | F8: Card taps a terminal; five dots light up one by one. | G8: =LEN(TRIM(E8))-LEN(SUBSTITUTE(TRIM(E8)," ",""))+1 | H8: =G8/$D$3
A9: 1 | B9: E | C9: Setup | D9: 12-18s | E9: Your card doesn't hold your money. It holds a number that points to your bank. | F9: Card morphs into a number, then an arrow to a bank icon. | G9: =LEN(TRIM(E9))-LEN(SUBSTITUTE(TRIM(E9)," ",""))+1 | H9: =G9/$D$3
A10: 1 | B10: E | C10: Mechanism | D10: 18-34s | E10: The terminal sends your request to the shop's bank. That bank passes it to the card network. The network finds your bank. Your bank checks your balance and fraud signals, then says yes or no. The answer races back. | F10: Left-to-right chain: Terminal > Shop's bank > Card network > Your bank. A glowing packet travels forward, then returns with a green tick. Step numbers 1-4 pop in. | G10: =LEN(TRIM(E10))-LEN(SUBSTITUTE(TRIM(E10)," ",""))+1 | H10: =G10/$D$3
A11: 1 | B11: E | C11: Payoff | D11: 34-43s | E11: But no money has moved yet. Those two seconds only bought a promise. Settlement, the real transfer, comes a day or two later. | F11: Chain greys out; a calendar flips forward. | G11: =LEN(TRIM(E11))-LEN(SUBSTITUTE(TRIM(E11)," ",""))+1 | H11: =G11/$D$3
A12: 1 | B12: E | C12: Congrats | D12: 43-47s | E12: Congrats, you just learned how a card payment works. | F12: Congrats card: teal check + chime (template). | G12: =LEN(TRIM(E12))-LEN(SUBSTITUTE(TRIM(E12)," ",""))+1 | H12: =G12/$D$3
A13: 1 | B13: E | C13: CTA | D13: 47-50s | E13: Follow Unpack and Explain for how things actually work. | F13: Logo + tagline card. | G13: =LEN(TRIM(E13))-LEN(SUBSTITUTE(TRIM(E13)," ",""))+1 | H13: =G13/$D$3
C14: Total | E14: =IF(AND(G14>=100,G14<=130),"Within the 100-130 word target","Outside the 100-130 word target") | G14: =SUM(G7:G13) | H14: =SUM(H7:H13)
C15: Sources / verify | D15: Verify: settlement timing varies by country and card network. Cite the source on screen.
C16: Caption + hashtags | D16: Tapping your card feels instant, but there's a whole relay behind it. Save this for the next time someone asks how card payments work. #howitworks #payments #fintech #explained
A18: Post 2 | E | How GPS finds you
A19: 2 | B19: E | C19: Question | D19: 0-3s | E19: Do you know how GPS actually finds you? | F19: Question card (template). | G19: =LEN(TRIM(E19))-LEN(SUBSTITUTE(TRIM(E19)," ",""))+1 | H19: =G19/$D$3
A20: 2 | B20: E | C20: Hook | D20: 3-6s | E20: GPS doesn't track you. Your phone just listens. | F20: Phone icon with ears/sound waves; satellite beams arrive, nothing goes back. | G20: =LEN(TRIM(E20))-LEN(SUBSTITUTE(TRIM(E20)," ",""))+1 | H20: =G20/$D$3
A21: 2 | B21: E | C21: Setup | D21: 6-12s | E21: About thirty GPS satellites orbit Earth, broadcasting precise timing signals and their positions. | F21: Orbit animation, satellites emitting expanding rings. | G21: =LEN(TRIM(E21))-LEN(SUBSTITUTE(TRIM(E21)," ",""))+1 | H21: =G21/$D$3
A22: 2 | B22: E | C22: Mechanism | D22: 12-28s | E22: Each signal carries the satellite's position and the exact moment it was sent. Your phone measures how late each signal arrives. Delay times the speed of light gives distance. Three satellites can illustrate how your position is calculated. A fourth lets your phone solve for its own clock error, too. | F22: Circles from 3 satellites overlap at one point; a 4th circle snaps in and a small clock icon corrects itself. | G22: =LEN(TRIM(E22))-LEN(SUBSTITUTE(TRIM(E22)," ",""))+1 | H22: =G22/$D$3
A23: 2 | B23: E | C23: Payoff | D23: 28-40s | E23: Your phone never sends anything back, so GPS works with no internet. And the satellites' clocks are corrected for relativity. Skip that, and you'd drift by several kilometers every day. | F23: Phone shows airplane mode and still has a location pin. Clock with a tiny correction arrow. | G23: =LEN(TRIM(E23))-LEN(SUBSTITUTE(TRIM(E23)," ",""))+1 | H23: =G23/$D$3
A24: 2 | B24: E | C24: Congrats | D24: 40-44s | E24: Congrats, you just learned how GPS finds you. | F24: Congrats card: teal check + chime (template). | G24: =LEN(TRIM(E24))-LEN(SUBSTITUTE(TRIM(E24)," ",""))+1 | H24: =G24/$D$3
A25: 2 | B25: E | C25: CTA | D25: 44-47s | E25: Follow Unpack and Explain for how things actually work. | F25: Logo + tagline card. | G25: =LEN(TRIM(E25))-LEN(SUBSTITUTE(TRIM(E25)," ",""))+1 | H25: =G25/$D$3
C26: Total | E26: =IF(AND(G26>=100,G26<=130),"Within the 100-130 word target","Outside the 100-130 word target") | G26: =SUM(G19:G25) | H26: =SUM(H19:H25)
C27: Sources / verify | D27: Verify: satellite count (about 30 operational), altitude, and the relativity drift figure (commonly cited around 10 km/day). Source: GPS.gov.
C28: Caption + hashtags | D28: Your phone doesn't talk to GPS satellites. It only listens. Save this for the next time you hear 'GPS is tracking me'. #GPS #howitworks #technology #explained
A30: Post 3 | F | How a jet engine works + Gimli Glider
A31: 3 | B31: F | C31: Question | D31: 0-4s | E31: Do you know how a jet engine actually works? | F31: Question card (template). | G31: =LEN(TRIM(E31))-LEN(SUBSTITUTE(TRIM(E31)," ",""))+1 | H31: =G31/$D$3
A32: 3 | B32: F | C32: Hook | D32: 4-10s | E32: In 1983, a passenger jet lost both engines at 41,000 feet. Everyone survived. Here's why. | F32: Plane silhouette high over clouds; engine glow cuts out. | G32: =LEN(TRIM(E32))-LEN(SUBSTITUTE(TRIM(E32)," ",""))+1 | H32: =G32/$D$3
A33: 3 | B33: F | C33: Setup | D33: 10-14s | E33: A jet engine is a machine that burns fuel without stopping. | F33: Cutaway of a turbofan engine. | G33: =LEN(TRIM(E33))-LEN(SUBSTITUTE(TRIM(E33)," ",""))+1 | H33: =G33/$D$3
A34: 3 | B34: F | C34: Mechanism | D34: 14-28s | E34: Suck: a fan pulls in air. Squeeze: a compressor packs it tight. Bang: fuel burns in the middle. Blow: hot gas spins a turbine, then blasts out the back and pushes the plane forward. | F34: Four labeled stages light up in order along the engine cutaway (Suck, Squeeze, Bang, Blow). | G34: =LEN(TRIM(E34))-LEN(SUBSTITUTE(TRIM(E34)," ",""))+1 | H34: =G34/$D$3
A35: 3 | B35: F | C35: Payoff | D35: 28-42s | E35: Air Canada Flight 143 ran dry after a pounds-versus-kilograms mix-up in the fuel calculation. The plane got less than half the fuel it needed. The pilots glided to an airfield in Gimli, Canada, and landed safely. | F35: Fuel gauge drains; unit labels lb and kg swap; glide path line arcs down to a runway. | G35: =LEN(TRIM(E35))-LEN(SUBSTITUTE(TRIM(E35)," ",""))+1 | H35: =G35/$D$3
A36: 3 | B36: F | C36: Congrats | D36: 42-46s | E36: Congrats, you just learned how a jet engine works. | F36: Congrats card: teal check + chime (template). | G36: =LEN(TRIM(E36))-LEN(SUBSTITUTE(TRIM(E36)," ",""))+1 | H36: =G36/$D$3
A37: 3 | B37: F | C37: CTA | D37: 46-49s | E37: Follow Unpack and Explain for how things actually work. | F37: Logo + tagline card. | G37: =LEN(TRIM(E37))-LEN(SUBSTITUTE(TRIM(E37)," ",""))+1 | H37: =G37/$D$3
C38: Total | E38: =IF(AND(G38>=100,G38<=130),"Within the 100-130 word target","Outside the 100-130 word target") | G38: =SUM(G31:G37) | H38: =SUM(H31:H37)
C39: Sources / verify | D39: Verify: altitude, fuel amounts, and that nobody was killed. Source: Canadian investigation report on Air Canada Flight 143. Keep the tone factual and credit the crew's skill.
C40: Caption + hashtags | D40: Both engines stopped at 41,000 feet and the crew still landed the plane. Here's how a jet engine works, and what went wrong. Save for later. #aviation #engineering #howitworks #explained
A42: Post 4 | Q | Myth: planes fly because air pushes up from below
A43: 4 | B43: Q | C43: Question | D43: 0-4s | E43: Do you know what really keeps a plane in the air? | F43: Question card (template). | G43: =LEN(TRIM(E43))-LEN(SUBSTITUTE(TRIM(E43)," ",""))+1 | H43: =G43/$D$3
A44: 4 | B44: Q | C44: Hook | D44: 4-9s | E44: Myth: planes fly because air pushes up on the wing from below. | F44: Wing cross-section with a red 'MYTH' stamp. | G44: =LEN(TRIM(E44))-LEN(SUBSTITUTE(TRIM(E44)," ",""))+1 | H44: =G44/$D$3
...

Sheet Summary
A1: Performance Summary
A2: Updates automatically from the Content Plan tab. Review after about 12-15 posts, then double down on the winning format.
A4: Progress
A5: Total planned posts | B5: =COUNTA('Content Plan'!$A$5:$A$24)
A6: Posted | B6: =COUNTIF('Content Plan'!$I$5:$I$24,"Posted")
A7: Progress | B7: =IFERROR(B6/B5,0)
A10: By format
A11: Format | B11: Planned | C11: Posted | D11: Avg reach | E11: Avg watch time % | F11: Avg share + save rate | G11: Avg follows per 1k reach
A12: E | B12: =COUNTIF('Content Plan'!$D$5:$D$24,A12) | C12: =COUNTIFS('Content Plan'!$D$5:$D$24,A12,'Content Plan'!$I$5:$I$24,"Posted") | D12: =IFERROR(AVERAGEIFS('Content Plan'!$J$5:$J$24,'Content Plan'!$D$5:$D$24,A12),"-") | E12: =IFERROR(AVERAGEIFS('Content Plan'!$K$5:$K$24,'Content Plan'!$D$5:$D$24,A12),"-") | F12: =IFERROR(AVERAGEIFS('Content Plan'!$R$5:$R$24,'Content Plan'!$D$5:$D$24,A12),"-") | G12: =IFERROR(AVERAGEIFS('Content Plan'!$S$5:$S$24,'Content Plan'!$D$5:$D$24,A12),"-")
A13: F | B13: =COUNTIF('Content Plan'!$D$5:$D$24,A13) | C13: =COUNTIFS('Content Plan'!$D$5:$D$24,A13,'Content Plan'!$I$5:$I$24,"Posted") | D13: =IFERROR(AVERAGEIFS('Content Plan'!$J$5:$J$24,'Content Plan'!$D$5:$D$24,A13),"-") | E13: =IFERROR(AVERAGEIFS('Content Plan'!$K$5:$K$24,'Content Plan'!$D$5:$D$24,A13),"-") | F13: =IFERROR(AVERAGEIFS('Content Plan'!$R$5:$R$24,'Content Plan'!$D$5:$D$24,A13),"-") | G13: =IFERROR(AVERAGEIFS('Content Plan'!$S$5:$S$24,'Content Plan'!$D$5:$D$24,A13),"-")
A14: Q | B14: =COUNTIF('Content Plan'!$D$5:$D$24,A14) | C14: =COUNTIFS('Content Plan'!$D$5:$D$24,A14,'Content Plan'!$I$5:$I$24,"Posted") | D14: =IFERROR(AVERAGEIFS('Content Plan'!$J$5:$J$24,'Content Plan'!$D$5:$D$24,A14),"-") | E14: =IFERROR(AVERAGEIFS('Content Plan'!$K$5:$K$24,'Content Plan'!$D$5:$D$24,A14),"-") | F14: =IFERROR(AVERAGEIFS('Content Plan'!$R$5:$R$24,'Content Plan'!$D$5:$D$24,A14),"-") | G14: =IFERROR(AVERAGEIFS('Content Plan'!$S$5:$S$24,'Content Plan'!$D$5:$D$24,A14),"-")
A15: Carousel | B15: =COUNTIF('Content Plan'!$D$5:$D$24,A15) | C15: =COUNTIFS('Content Plan'!$D$5:$D$24,A15,'Content Plan'!$I$5:$I$24,"Posted") | D15: =IFERROR(AVERAGEIFS('Content Plan'!$J$5:$J$24,'Content Plan'!$D$5:$D$24,A15),"-") | E15: =IFERROR(AVERAGEIFS('Content Plan'!$K$5:$K$24,'Content Plan'!$D$5:$D$24,A15),"-") | F15: =IFERROR(AVERAGEIFS('Content Plan'!$R$5:$R$24,'Content Plan'!$D$5:$D$24,A15),"-") | G15: =IFERROR(AVERAGEIFS('Content Plan'!$S$5:$S$24,'Content Plan'!$D$5:$D$24,A15),"-")
A17: Best format so far
A18: By average watch time | B18: =IFERROR(INDEX($A$12:$A$15,MATCH(MAX(E12:E15),E12:E15,0)),"-")
A19: By share + save rate | B19: =IFERROR(INDEX($A$12:$A$15,MATCH(MAX(F12:F15),F12:F15,0)),"-")
A20: By follows per 1k reach | B20: =IFERROR(INDEX($A$12:$A$15,MATCH(MAX(G12:G15),G12:G15,0)),"-")
A22: Decision checkpoint: once about 12-15 posts are live, shift your mix toward whichever format wins on watch time, shares/saves, and follows. Small samples can mislead, so compare formats only when each has at least 3 posts.

Sheet Brand
A1: Unpack & Explain: Brand Kit
A2: Tagline: How things actually work.
A4: Role | B4: Name | C4: Hex | D4: Swatch | E4: Use
A5: Background / text | B5: Slate Navy | C5: #0F172A | E5: Reel backgrounds (radial to #1E293B)
A6: Primary | B6: Brand Teal | C6: #2DD4BF | E6: Diagrams, key highlights, 'correct', FACT stamp
A7: Accent | B7: Signal Amber | C7: #F59E0B | E7: Numbers, keywords, active caption word
A8: Failure tag | B8: Alert Coral | C8: #FF5A5F | E8: Only F-post failure segments, MYTH stamp, 'wrong' marks
A9: Light background | B9: Cloud White | C9: #F7F9FC | E9: Carousels and light cards
A10: Secondary text | B10: Slate | C10: #94A3B8 | E10: Sources, small labels on dark backgrounds
A12: Typography and template rules
A13: Headline font | B13: Poppins SemiBold (free on Google Fonts)
A14: Body / caption font | B14: Inter Regular or Medium (free on Google Fonts)
A15: Captions | B15: Burned in on every reel, high contrast, 1-2 lines max | E15: Many people watch muted
A16: Intro | B16: Under 1 second: logo sting plus the hook text | E16: Hook must land in the first 3 seconds
A17: Diagram style | B17: Flat shapes, 2-3 colors per scene, one idea per step | E17: Reuse a master template so each reel is assembly
A18: Voiceover | B18: Neutral AI voice, one voice for every reel | E18: Consistency builds recognition
A19: Sources | B19: Name the source on screen in the last 3 seconds of F posts | E19: Builds trust
A20: Units | B20: Show both metric and imperial where it matters | E20: Global audience
A21: Handle ideas | B21: @unpackandexplain, @unpack.explain, @unpackexplain | E21: Check availability on Instagram first
